<mujoco>
  <asset>
    <texture type="cube" name="hero_body_texture" file="/home/artalmaz31/tung_playground/heroes/tung_tung_sahur/body.png"/>
    <texture type="cube" name="hero_leg_texture" file="/home/artalmaz31/tung_playground/heroes/tung_tung_sahur/leg.png"/>
    <material name="hero_body_material" texture="hero_body_texture"/>
    <material name="hero_leg_material" texture="hero_leg_texture"/>
  </asset>
  <worldbody>
    <light diffuse=".5 .5 .5" pos="0 0 3" dir="0 0 -1"/>
    <geom type="plane" size="1 1 0.1" rgba=".9 0 0 1"/>
    <body name="torso" pos="0 0 1.5">
      <joint type="free"/>
      <!-- <geom type="box" size=".2 .3 .5"/> -->
      <geom type="box" size=".2 .3 .5" material="hero_body_material"/>
      <body name="leg1" pos="0 .15 .0">
        <joint type="hinge" axis="1 0 0" pos="0 0 -.4"/>
        <geom type="box" size=".1 .1 .3" material="hero_leg_material"/>
      </body>
      <body name="leg2" pos="0 -.15 .0">
        <joint type="hinge" axis="1 0 0" pos="0 0 -.4"/>
        <geom type="box" size=".1 .1 .3" material="hero_leg_material"/>
      </body>
    </body>
  </worldbody>
</mujoco>
