<mujoco>
  <asset>
    <texture type="2d" name="hero_texture" file="heroes/complexo/texture.png"/>
    <material name="hero_material" texture="hero_texture"/>
  </asset>
  <worldbody>
    <light diffuse=".5 .5 .5" pos="0 0 3" dir="0 0 -1"/>
    <geom type="plane" size="1 1 0.1" rgba=".9 0 0 1"/>
    <body name="torso" pos="0 0 1.5">
      <joint type="free"/>
      <geom type="box" size=".2 .3 .5" material="hero_material"/>
      <body name="leg1" pos="0 .15 .0">
        <joint type="hinge" axis="1 0 0" pos="0 0 -.4"/>
        <geom type="capsule" size=".05 .2" rgba="0 0 .9 1"/>
      </body>
      <body name="leg2" pos="0 -.15 .0">
        <joint type="hinge" axis="1 0 0" pos="0 0 -.4"/>
        <geom type="capsule" size=".05 .2" rgba="0 0 .9 1"/>
      </body>
    </body>
  </worldbody>
</mujoco>
