<?xml version="1.0"?>
<robot name="tung_hero">

  <!-- Base Link -->
  <link name="base_link">
    <visual>
      <origin xyz="0 0 0" rpy="0 0 0"/>
      <geometry>
        <mesh filename="generated_mesh.obj" scale="1 1 1"/>
      </geometry>
      <material name="hero_material">
        <color rgba="0.8 0.6 0.2 1.0"/>
      </material>
    </visual>
    <collision>
      <origin xyz="0 0 0" rpy="0 0 0"/>
      <geometry>
        <mesh filename="generated_mesh.obj" scale="1 1 1"/>
      </geometry>
    </collision>
    <inertial>
      <origin xyz="0 0 0" rpy="0 0 0"/>
      <mass value="1.0"/>
      <inertia ixx="0.1" ixy="0" ixz="0" iyy="0.1" iyz="0" izz="0.1"/>
    </inertial>
  </link>

  <!-- Link for pelvis -->
  <link name="pelvis_link">
    <visual>
      <origin xyz="0 0 0" rpy="0 0 0"/>
      <geometry>
        <box size="0.05 0.05 0.05"/>
      </geometry>
      <material name="joint_material">
        <color rgba="0.2 0.2 0.8 1.0"/>
      </material>
    </visual>
    <collision>
      <origin xyz="0 0 0" rpy="0 0 0"/>
      <geometry>
        <box size="0.05 0.05 0.05"/>
      </geometry>
    </collision>
    <inertial>
      <origin xyz="0 0 0" rpy="0 0 0"/>
      <mass value="0.1"/>
      <inertia ixx="0.01" ixy="0" ixz="0" iyy="0.01" iyz="0" izz="0.01"/>
    </inertial>
  </link>

  <!-- Link for spine -->
  <link name="spine_link">
    <visual>
      <origin xyz="0 0 0" rpy="0 0 0"/>
      <geometry>
        <box size="0.05 0.05 0.05"/>
      </geometry>
      <material name="joint_material">
        <color rgba="0.2 0.2 0.8 1.0"/>
      </material>
    </visual>
    <collision>
      <origin xyz="0 0 0" rpy="0 0 0"/>
      <geometry>
        <box size="0.05 0.05 0.05"/>
      </geometry>
    </collision>
    <inertial>
      <origin xyz="0 0 0" rpy="0 0 0"/>
      <mass value="0.1"/>
      <inertia ixx="0.01" ixy="0" ixz="0" iyy="0.01" iyz="0" izz="0.01"/>
    </inertial>
  </link>

  <!-- Link for chest -->
  <link name="chest_link">
    <visual>
      <origin xyz="0 0 0" rpy="0 0 0"/>
      <geometry>
        <box size="0.05 0.05 0.05"/>
      </geometry>
      <material name="joint_material">
        <color rgba="0.2 0.2 0.8 1.0"/>
      </material>
    </visual>
    <collision>
      <origin xyz="0 0 0" rpy="0 0 0"/>
      <geometry>
        <box size="0.05 0.05 0.05"/>
      </geometry>
    </collision>
    <inertial>
      <origin xyz="0 0 0" rpy="0 0 0"/>
      <mass value="0.1"/>
      <inertia ixx="0.01" ixy="0" ixz="0" iyy="0.01" iyz="0" izz="0.01"/>
    </inertial>
  </link>

  <!-- Link for neck -->
  <link name="neck_link">
    <visual>
      <origin xyz="0 0 0" rpy="0 0 0"/>
      <geometry>
        <box size="0.05 0.05 0.05"/>
      </geometry>
      <material name="joint_material">
        <color rgba="0.2 0.2 0.8 1.0"/>
      </material>
    </visual>
    <collision>
      <origin xyz="0 0 0" rpy="0 0 0"/>
      <geometry>
        <box size="0.05 0.05 0.05"/>
      </geometry>
    </collision>
    <inertial>
      <origin xyz="0 0 0" rpy="0 0 0"/>
      <mass value="0.1"/>
      <inertia ixx="0.01" ixy="0" ixz="0" iyy="0.01" iyz="0" izz="0.01"/>
    </inertial>
  </link>

  <!-- Link for head -->
  <link name="head_link">
    <visual>
      <origin xyz="0 0 0" rpy="0 0 0"/>
      <geometry>
        <box size="0.05 0.05 0.05"/>
      </geometry>
      <material name="joint_material">
        <color rgba="0.2 0.2 0.8 1.0"/>
      </material>
    </visual>
    <collision>
      <origin xyz="0 0 0" rpy="0 0 0"/>
      <geometry>
        <box size="0.05 0.05 0.05"/>
      </geometry>
    </collision>
    <inertial>
      <origin xyz="0 0 0" rpy="0 0 0"/>
      <mass value="0.1"/>
      <inertia ixx="0.01" ixy="0" ixz="0" iyy="0.01" iyz="0" izz="0.01"/>
    </inertial>
  </link>

  <!-- Link for left_shoulder -->
  <link name="left_shoulder_link">
    <visual>
      <origin xyz="0 0 0" rpy="0 0 0"/>
      <geometry>
        <box size="0.05 0.05 0.05"/>
      </geometry>
      <material name="joint_material">
        <color rgba="0.2 0.2 0.8 1.0"/>
      </material>
    </visual>
    <collision>
      <origin xyz="0 0 0" rpy="0 0 0"/>
      <geometry>
        <box size="0.05 0.05 0.05"/>
      </geometry>
    </collision>
    <inertial>
      <origin xyz="0 0 0" rpy="0 0 0"/>
      <mass value="0.1"/>
      <inertia ixx="0.01" ixy="0" ixz="0" iyy="0.01" iyz="0" izz="0.01"/>
    </inertial>
  </link>

  <!-- Link for left_upper_arm -->
  <link name="left_upper_arm_link">
    <visual>
      <origin xyz="0 0 0" rpy="0 0 0"/>
      <geometry>
        <box size="0.05 0.05 0.05"/>
      </geometry>
      <material name="joint_material">
        <color rgba="0.2 0.2 0.8 1.0"/>
      </material>
    </visual>
    <collision>
      <origin xyz="0 0 0" rpy="0 0 0"/>
      <geometry>
        <box size="0.05 0.05 0.05"/>
      </geometry>
    </collision>
    <inertial>
      <origin xyz="0 0 0" rpy="0 0 0"/>
      <mass value="0.1"/>
      <inertia ixx="0.01" ixy="0" ixz="0" iyy="0.01" iyz="0" izz="0.01"/>
    </inertial>
  </link>

  <!-- Link for left_lower_arm -->
  <link name="left_lower_arm_link">
    <visual>
      <origin xyz="0 0 0" rpy="0 0 0"/>
      <geometry>
        <box size="0.05 0.05 0.05"/>
      </geometry>
      <material name="joint_material">
        <color rgba="0.2 0.2 0.8 1.0"/>
      </material>
    </visual>
    <collision>
      <origin xyz="0 0 0" rpy="0 0 0"/>
      <geometry>
        <box size="0.05 0.05 0.05"/>
      </geometry>
    </collision>
    <inertial>
      <origin xyz="0 0 0" rpy="0 0 0"/>
      <mass value="0.1"/>
      <inertia ixx="0.01" ixy="0" ixz="0" iyy="0.01" iyz="0" izz="0.01"/>
    </inertial>
  </link>

  <!-- Link for left_hand -->
  <link name="left_hand_link">
    <visual>
      <origin xyz="0 0 0" rpy="0 0 0"/>
      <geometry>
        <box size="0.05 0.05 0.05"/>
      </geometry>
      <material name="joint_material">
        <color rgba="0.2 0.2 0.8 1.0"/>
      </material>
    </visual>
    <collision>
      <origin xyz="0 0 0" rpy="0 0 0"/>
      <geometry>
        <box size="0.05 0.05 0.05"/>
      </geometry>
    </collision>
    <inertial>
      <origin xyz="0 0 0" rpy="0 0 0"/>
      <mass value="0.1"/>
      <inertia ixx="0.01" ixy="0" ixz="0" iyy="0.01" iyz="0" izz="0.01"/>
    </inertial>
  </link>

  <!-- Link for right_shoulder -->
  <link name="right_shoulder_link">
    <visual>
      <origin xyz="0 0 0" rpy="0 0 0"/>
      <geometry>
        <box size="0.05 0.05 0.05"/>
      </geometry>
      <material name="joint_material">
        <color rgba="0.2 0.2 0.8 1.0"/>
      </material>
    </visual>
    <collision>
      <origin xyz="0 0 0" rpy="0 0 0"/>
      <geometry>
        <box size="0.05 0.05 0.05"/>
      </geometry>
    </collision>
    <inertial>
      <origin xyz="0 0 0" rpy="0 0 0"/>
      <mass value="0.1"/>
      <inertia ixx="0.01" ixy="0" ixz="0" iyy="0.01" iyz="0" izz="0.01"/>
    </inertial>
  </link>

  <!-- Link for right_upper_arm -->
  <link name="right_upper_arm_link">
    <visual>
      <origin xyz="0 0 0" rpy="0 0 0"/>
      <geometry>
        <box size="0.05 0.05 0.05"/>
      </geometry>
      <material name="joint_material">
        <color rgba="0.2 0.2 0.8 1.0"/>
      </material>
    </visual>
    <collision>
      <origin xyz="0 0 0" rpy="0 0 0"/>
      <geometry>
        <box size="0.05 0.05 0.05"/>
      </geometry>
    </collision>
    <inertial>
      <origin xyz="0 0 0" rpy="0 0 0"/>
      <mass value="0.1"/>
      <inertia ixx="0.01" ixy="0" ixz="0" iyy="0.01" iyz="0" izz="0.01"/>
    </inertial>
  </link>

  <!-- Link for right_lower_arm -->
  <link name="right_lower_arm_link">
    <visual>
      <origin xyz="0 0 0" rpy="0 0 0"/>
      <geometry>
        <box size="0.05 0.05 0.05"/>
      </geometry>
      <material name="joint_material">
        <color rgba="0.2 0.2 0.8 1.0"/>
      </material>
    </visual>
    <collision>
      <origin xyz="0 0 0" rpy="0 0 0"/>
      <geometry>
        <box size="0.05 0.05 0.05"/>
      </geometry>
    </collision>
    <inertial>
      <origin xyz="0 0 0" rpy="0 0 0"/>
      <mass value="0.1"/>
      <inertia ixx="0.01" ixy="0" ixz="0" iyy="0.01" iyz="0" izz="0.01"/>
    </inertial>
  </link>

  <!-- Link for right_hand -->
  <link name="right_hand_link">
    <visual>
      <origin xyz="0 0 0" rpy="0 0 0"/>
      <geometry>
        <box size="0.05 0.05 0.05"/>
      </geometry>
      <material name="joint_material">
        <color rgba="0.2 0.2 0.8 1.0"/>
      </material>
    </visual>
    <collision>
      <origin xyz="0 0 0" rpy="0 0 0"/>
      <geometry>
        <box size="0.05 0.05 0.05"/>
      </geometry>
    </collision>
    <inertial>
      <origin xyz="0 0 0" rpy="0 0 0"/>
      <mass value="0.1"/>
      <inertia ixx="0.01" ixy="0" ixz="0" iyy="0.01" iyz="0" izz="0.01"/>
    </inertial>
  </link>

  <!-- Link for left_hip -->
  <link name="left_hip_link">
    <visual>
      <origin xyz="0 0 0" rpy="0 0 0"/>
      <geometry>
        <box size="0.05 0.05 0.05"/>
      </geometry>
      <material name="joint_material">
        <color rgba="0.2 0.2 0.8 1.0"/>
      </material>
    </visual>
    <collision>
      <origin xyz="0 0 0" rpy="0 0 0"/>
      <geometry>
        <box size="0.05 0.05 0.05"/>
      </geometry>
    </collision>
    <inertial>
      <origin xyz="0 0 0" rpy="0 0 0"/>
      <mass value="0.1"/>
      <inertia ixx="0.01" ixy="0" ixz="0" iyy="0.01" iyz="0" izz="0.01"/>
    </inertial>
  </link>

  <!-- Link for left_upper_leg -->
  <link name="left_upper_leg_link">
    <visual>
      <origin xyz="0 0 0" rpy="0 0 0"/>
      <geometry>
        <box size="0.05 0.05 0.05"/>
      </geometry>
      <material name="joint_material">
        <color rgba="0.2 0.2 0.8 1.0"/>
      </material>
    </visual>
    <collision>
      <origin xyz="0 0 0" rpy="0 0 0"/>
      <geometry>
        <box size="0.05 0.05 0.05"/>
      </geometry>
    </collision>
    <inertial>
      <origin xyz="0 0 0" rpy="0 0 0"/>
      <mass value="0.1"/>
      <inertia ixx="0.01" ixy="0" ixz="0" iyy="0.01" iyz="0" izz="0.01"/>
    </inertial>
  </link>

  <!-- Link for left_lower_leg -->
  <link name="left_lower_leg_link">
    <visual>
      <origin xyz="0 0 0" rpy="0 0 0"/>
      <geometry>
        <box size="0.05 0.05 0.05"/>
      </geometry>
      <material name="joint_material">
        <color rgba="0.2 0.2 0.8 1.0"/>
      </material>
    </visual>
    <collision>
      <origin xyz="0 0 0" rpy="0 0 0"/>
      <geometry>
        <box size="0.05 0.05 0.05"/>
      </geometry>
    </collision>
    <inertial>
      <origin xyz="0 0 0" rpy="0 0 0"/>
      <mass value="0.1"/>
      <inertia ixx="0.01" ixy="0" ixz="0" iyy="0.01" iyz="0" izz="0.01"/>
    </inertial>
  </link>

  <!-- Link for left_foot -->
  <link name="left_foot_link">
    <visual>
      <origin xyz="0 0 0" rpy="0 0 0"/>
      <geometry>
        <box size="0.05 0.05 0.05"/>
      </geometry>
      <material name="joint_material">
        <color rgba="0.2 0.2 0.8 1.0"/>
      </material>
    </visual>
    <collision>
      <origin xyz="0 0 0" rpy="0 0 0"/>
      <geometry>
        <box size="0.05 0.05 0.05"/>
      </geometry>
    </collision>
    <inertial>
      <origin xyz="0 0 0" rpy="0 0 0"/>
      <mass value="0.1"/>
      <inertia ixx="0.01" ixy="0" ixz="0" iyy="0.01" iyz="0" izz="0.01"/>
    </inertial>
  </link>

  <!-- Link for right_hip -->
  <link name="right_hip_link">
    <visual>
      <origin xyz="0 0 0" rpy="0 0 0"/>
      <geometry>
        <box size="0.05 0.05 0.05"/>
      </geometry>
      <material name="joint_material">
        <color rgba="0.2 0.2 0.8 1.0"/>
      </material>
    </visual>
    <collision>
      <origin xyz="0 0 0" rpy="0 0 0"/>
      <geometry>
        <box size="0.05 0.05 0.05"/>
      </geometry>
    </collision>
    <inertial>
      <origin xyz="0 0 0" rpy="0 0 0"/>
      <mass value="0.1"/>
      <inertia ixx="0.01" ixy="0" ixz="0" iyy="0.01" iyz="0" izz="0.01"/>
    </inertial>
  </link>

  <!-- Link for right_upper_leg -->
  <link name="right_upper_leg_link">
    <visual>
      <origin xyz="0 0 0" rpy="0 0 0"/>
      <geometry>
        <box size="0.05 0.05 0.05"/>
      </geometry>
      <material name="joint_material">
        <color rgba="0.2 0.2 0.8 1.0"/>
      </material>
    </visual>
    <collision>
      <origin xyz="0 0 0" rpy="0 0 0"/>
      <geometry>
        <box size="0.05 0.05 0.05"/>
      </geometry>
    </collision>
    <inertial>
      <origin xyz="0 0 0" rpy="0 0 0"/>
      <mass value="0.1"/>
      <inertia ixx="0.01" ixy="0" ixz="0" iyy="0.01" iyz="0" izz="0.01"/>
    </inertial>
  </link>

  <!-- Link for right_lower_leg -->
  <link name="right_lower_leg_link">
    <visual>
      <origin xyz="0 0 0" rpy="0 0 0"/>
      <geometry>
        <box size="0.05 0.05 0.05"/>
      </geometry>
      <material name="joint_material">
        <color rgba="0.2 0.2 0.8 1.0"/>
      </material>
    </visual>
    <collision>
      <origin xyz="0 0 0" rpy="0 0 0"/>
      <geometry>
        <box size="0.05 0.05 0.05"/>
      </geometry>
    </collision>
    <inertial>
      <origin xyz="0 0 0" rpy="0 0 0"/>
      <mass value="0.1"/>
      <inertia ixx="0.01" ixy="0" ixz="0" iyy="0.01" iyz="0" izz="0.01"/>
    </inertial>
  </link>

  <!-- Link for right_foot -->
  <link name="right_foot_link">
    <visual>
      <origin xyz="0 0 0" rpy="0 0 0"/>
      <geometry>
        <box size="0.05 0.05 0.05"/>
      </geometry>
      <material name="joint_material">
        <color rgba="0.2 0.2 0.8 1.0"/>
      </material>
    </visual>
    <collision>
      <origin xyz="0 0 0" rpy="0 0 0"/>
      <geometry>
        <box size="0.05 0.05 0.05"/>
      </geometry>
    </collision>
    <inertial>
      <origin xyz="0 0 0" rpy="0 0 0"/>
      <mass value="0.1"/>
      <inertia ixx="0.01" ixy="0" ixz="0" iyy="0.01" iyz="0" izz="0.01"/>
    </inertial>
  </link>

  <!-- Joint: root_to_pelvis -->
  <joint name="root_to_pelvis" type="revolute">
    <parent link="base_link"/>
    <child link="pelvis_link"/>
    <origin xyz="0.000 0.800 0.000" rpy="0 0 0"/>
    <axis xyz="0 0 1"/>
    <limit lower="-3.14159" upper="3.14159" effort="100" velocity="10"/>
    <dynamics damping="0.1" friction="0.1"/>
  </joint>

  <!-- Joint: pelvis_to_spine -->
  <joint name="pelvis_to_spine" type="revolute">
    <parent link="pelvis_link"/>
    <child link="spine_link"/>
    <origin xyz="0.000 1.000 0.000" rpy="0 0 0"/>
    <axis xyz="0 0 1"/>
    <limit lower="-3.14159" upper="3.14159" effort="100" velocity="10"/>
    <dynamics damping="0.1" friction="0.1"/>
  </joint>

  <!-- Joint: spine_to_chest -->
  <joint name="spine_to_chest" type="revolute">
    <parent link="spine_link"/>
    <child link="chest_link"/>
    <origin xyz="0.000 1.200 0.000" rpy="0 0 0"/>
    <axis xyz="0 0 1"/>
    <limit lower="-3.14159" upper="3.14159" effort="100" velocity="10"/>
    <dynamics damping="0.1" friction="0.1"/>
  </joint>

  <!-- Joint: chest_to_neck -->
  <joint name="chest_to_neck" type="revolute">
    <parent link="chest_link"/>
    <child link="neck_link"/>
    <origin xyz="0.000 1.500 0.000" rpy="0 0 0"/>
    <axis xyz="0 0 1"/>
    <limit lower="-3.14159" upper="3.14159" effort="100" velocity="10"/>
    <dynamics damping="0.1" friction="0.1"/>
  </joint>

  <!-- Joint: neck_to_head -->
  <joint name="neck_to_head" type="revolute">
    <parent link="neck_link"/>
    <child link="head_link"/>
    <origin xyz="0.000 1.700 0.000" rpy="0 0 0"/>
    <axis xyz="0 0 1"/>
    <limit lower="-3.14159" upper="3.14159" effort="100" velocity="10"/>
    <dynamics damping="0.1" friction="0.1"/>
  </joint>

  <!-- Joint: chest_to_left_shoulder -->
  <joint name="chest_to_left_shoulder" type="revolute">
    <parent link="chest_link"/>
    <child link="left_shoulder_link"/>
    <origin xyz="-0.200 1.300 0.000" rpy="0 0 0"/>
    <axis xyz="0 0 1"/>
    <limit lower="-3.14159" upper="3.14159" effort="100" velocity="10"/>
    <dynamics damping="0.1" friction="0.1"/>
  </joint>

  <!-- Joint: left_shoulder_to_left_upper_arm -->
  <joint name="left_shoulder_to_left_upper_arm" type="revolute">
    <parent link="left_shoulder_link"/>
    <child link="left_upper_arm_link"/>
    <origin xyz="-0.300 1.100 0.000" rpy="0 0 0"/>
    <axis xyz="0 0 1"/>
    <limit lower="-3.14159" upper="3.14159" effort="100" velocity="10"/>
    <dynamics damping="0.1" friction="0.1"/>
  </joint>

  <!-- Joint: left_upper_arm_to_left_lower_arm -->
  <joint name="left_upper_arm_to_left_lower_arm" type="revolute">
    <parent link="left_upper_arm_link"/>
    <child link="left_lower_arm_link"/>
    <origin xyz="-0.300 0.700 0.000" rpy="0 0 0"/>
    <axis xyz="0 0 1"/>
    <limit lower="-3.14159" upper="3.14159" effort="100" velocity="10"/>
    <dynamics damping="0.1" friction="0.1"/>
  </joint>

  <!-- Joint: left_lower_arm_to_left_hand -->
  <joint name="left_lower_arm_to_left_hand" type="revolute">
    <parent link="left_lower_arm_link"/>
    <child link="left_hand_link"/>
    <origin xyz="-0.300 0.400 0.000" rpy="0 0 0"/>
    <axis xyz="0 0 1"/>
    <limit lower="-3.14159" upper="3.14159" effort="100" velocity="10"/>
    <dynamics damping="0.1" friction="0.1"/>
  </joint>

  <!-- Joint: chest_to_right_shoulder -->
  <joint name="chest_to_right_shoulder" type="revolute">
    <parent link="chest_link"/>
    <child link="right_shoulder_link"/>
    <origin xyz="0.200 1.300 0.000" rpy="0 0 0"/>
    <axis xyz="0 0 1"/>
    <limit lower="-3.14159" upper="3.14159" effort="100" velocity="10"/>
    <dynamics damping="0.1" friction="0.1"/>
  </joint>

  <!-- Joint: right_shoulder_to_right_upper_arm -->
  <joint name="right_shoulder_to_right_upper_arm" type="revolute">
    <parent link="right_shoulder_link"/>
    <child link="right_upper_arm_link"/>
    <origin xyz="0.300 1.100 0.000" rpy="0 0 0"/>
    <axis xyz="0 0 1"/>
    <limit lower="-3.14159" upper="3.14159" effort="100" velocity="10"/>
    <dynamics damping="0.1" friction="0.1"/>
  </joint>

  <!-- Joint: right_upper_arm_to_right_lower_arm -->
  <joint name="right_upper_arm_to_right_lower_arm" type="revolute">
    <parent link="right_upper_arm_link"/>
    <child link="right_lower_arm_link"/>
    <origin xyz="0.300 0.700 0.000" rpy="0 0 0"/>
    <axis xyz="0 0 1"/>
    <limit lower="-3.14159" upper="3.14159" effort="100" velocity="10"/>
    <dynamics damping="0.1" friction="0.1"/>
  </joint>

  <!-- Joint: right_lower_arm_to_right_hand -->
  <joint name="right_lower_arm_to_right_hand" type="revolute">
    <parent link="right_lower_arm_link"/>
    <child link="right_hand_link"/>
    <origin xyz="0.300 0.400 0.000" rpy="0 0 0"/>
    <axis xyz="0 0 1"/>
    <limit lower="-3.14159" upper="3.14159" effort="100" velocity="10"/>
    <dynamics damping="0.1" friction="0.1"/>
  </joint>

  <!-- Joint: pelvis_to_left_hip -->
  <joint name="pelvis_to_left_hip" type="revolute">
    <parent link="pelvis_link"/>
    <child link="left_hip_link"/>
    <origin xyz="-0.100 0.700 0.000" rpy="0 0 0"/>
    <axis xyz="0 0 1"/>
    <limit lower="-3.14159" upper="3.14159" effort="100" velocity="10"/>
    <dynamics damping="0.1" friction="0.1"/>
  </joint>

  <!-- Joint: left_hip_to_left_upper_leg -->
  <joint name="left_hip_to_left_upper_leg" type="revolute">
    <parent link="left_hip_link"/>
    <child link="left_upper_leg_link"/>
    <origin xyz="-0.100 0.400 0.000" rpy="0 0 0"/>
    <axis xyz="0 0 1"/>
    <limit lower="-3.14159" upper="3.14159" effort="100" velocity="10"/>
    <dynamics damping="0.1" friction="0.1"/>
  </joint>

  <!-- Joint: left_upper_leg_to_left_lower_leg -->
  <joint name="left_upper_leg_to_left_lower_leg" type="revolute">
    <parent link="left_upper_leg_link"/>
    <child link="left_lower_leg_link"/>
    <origin xyz="-0.100 0.000 0.000" rpy="0 0 0"/>
    <axis xyz="0 0 1"/>
    <limit lower="-3.14159" upper="3.14159" effort="100" velocity="10"/>
    <dynamics damping="0.1" friction="0.1"/>
  </joint>

  <!-- Joint: left_lower_leg_to_left_foot -->
  <joint name="left_lower_leg_to_left_foot" type="revolute">
    <parent link="left_lower_leg_link"/>
    <child link="left_foot_link"/>
    <origin xyz="-0.100 -0.300 0.000" rpy="0 0 0"/>
    <axis xyz="0 0 1"/>
    <limit lower="-3.14159" upper="3.14159" effort="100" velocity="10"/>
    <dynamics damping="0.1" friction="0.1"/>
  </joint>

  <!-- Joint: pelvis_to_right_hip -->
  <joint name="pelvis_to_right_hip" type="revolute">
    <parent link="pelvis_link"/>
    <child link="right_hip_link"/>
    <origin xyz="0.100 0.700 0.000" rpy="0 0 0"/>
    <axis xyz="0 0 1"/>
    <limit lower="-3.14159" upper="3.14159" effort="100" velocity="10"/>
    <dynamics damping="0.1" friction="0.1"/>
  </joint>

  <!-- Joint: right_hip_to_right_upper_leg -->
  <joint name="right_hip_to_right_upper_leg" type="revolute">
    <parent link="right_hip_link"/>
    <child link="right_upper_leg_link"/>
    <origin xyz="0.100 0.400 0.000" rpy="0 0 0"/>
    <axis xyz="0 0 1"/>
    <limit lower="-3.14159" upper="3.14159" effort="100" velocity="10"/>
    <dynamics damping="0.1" friction="0.1"/>
  </joint>

  <!-- Joint: right_upper_leg_to_right_lower_leg -->
  <joint name="right_upper_leg_to_right_lower_leg" type="revolute">
    <parent link="right_upper_leg_link"/>
    <child link="right_lower_leg_link"/>
    <origin xyz="0.100 0.000 0.000" rpy="0 0 0"/>
    <axis xyz="0 0 1"/>
    <limit lower="-3.14159" upper="3.14159" effort="100" velocity="10"/>
    <dynamics damping="0.1" friction="0.1"/>
  </joint>

  <!-- Joint: right_lower_leg_to_right_foot -->
  <joint name="right_lower_leg_to_right_foot" type="revolute">
    <parent link="right_lower_leg_link"/>
    <child link="right_foot_link"/>
    <origin xyz="0.100 -0.300 0.000" rpy="0 0 0"/>
    <axis xyz="0 0 1"/>
    <limit lower="-3.14159" upper="3.14159" effort="100" velocity="10"/>
    <dynamics damping="0.1" friction="0.1"/>
  </joint>

</robot>